2024-04-28 13:49:45,634 - ERROR - Cause exception while process update id=564117057 by bot id=6802573095
TelegramBadRequest: Telegram server says - Bad Request: file must be non-empty
Traceback (most recent call last):
  File "C:\Users\Treid Computers\PycharmProjects\Final_projects_4\.venv\Lib\site-packages\aiogram\dispatcher\dispatcher.py", line 309, in _process_update
    response = await self.feed_update(bot, update, **kwargs)
               ^^^^^^^^^^^^^^^^^^^^^^^^^^^^^^^^^^^^^^^^^^^^^
  File "C:\Users\Treid Computers\PycharmProjects\Final_projects_4\.venv\Lib\site-packages\aiogram\dispatcher\dispatcher.py", line 158, in feed_update
    response = await self.update.wrap_outer_middleware(
               ^^^^^^^^^^^^^^^^^^^^^^^^^^^^^^^^^^^^^^^^
  File "C:\Users\Treid Computers\PycharmProjects\Final_projects_4\.venv\Lib\site-packages\aiogram\dispatcher\middlewares\error.py", line 25, in __call__
    return await handler(event, data)
           ^^^^^^^^^^^^^^^^^^^^^^^^^^
  File "C:\Users\Treid Computers\PycharmProjects\Final_projects_4\.venv\Lib\site-packages\aiogram\dispatcher\middlewares\user_context.py", line 49, in __call__
    return await handler(event, data)
           ^^^^^^^^^^^^^^^^^^^^^^^^^^
  File "C:\Users\Treid Computers\PycharmProjects\Final_projects_4\.venv\Lib\site-packages\aiogram\fsm\middleware.py", line 42, in __call__
    return await handler(event, data)
           ^^^^^^^^^^^^^^^^^^^^^^^^^^
  File "C:\Users\Treid Computers\PycharmProjects\Final_projects_4\.venv\Lib\site-packages\aiogram\dispatcher\event\telegram.py", line 121, in trigger
    return await wrapped_inner(event, kwargs)
           ^^^^^^^^^^^^^^^^^^^^^^^^^^^^^^^^^^
  File "C:\Users\Treid Computers\PycharmProjects\Final_projects_4\.venv\Lib\site-packages\aiogram\dispatcher\event\handler.py", line 43, in call
    return await wrapped()
           ^^^^^^^^^^^^^^^
  File "C:\Users\Treid Computers\PycharmProjects\Final_projects_4\.venv\Lib\site-packages\aiogram\dispatcher\dispatcher.py", line 276, in _listen_update
    return await self.propagate_event(update_type=update_type, event=event, **kwargs)
           ^^^^^^^^^^^^^^^^^^^^^^^^^^^^^^^^^^^^^^^^^^^^^^^^^^^^^^^^^^^^^^^^^^^^^^^^^^
  File "C:\Users\Treid Computers\PycharmProjects\Final_projects_4\.venv\Lib\site-packages\aiogram\dispatcher\router.py", line 142, in propagate_event
    return await observer.wrap_outer_middleware(_wrapped, event=event, data=kwargs)
           ^^^^^^^^^^^^^^^^^^^^^^^^^^^^^^^^^^^^^^^^^^^^^^^^^^^^^^^^^^^^^^^^^^^^^^^^
  File "C:\Users\Treid Computers\PycharmProjects\Final_projects_4\.venv\Lib\site-packages\aiogram\dispatcher\router.py", line 137, in _wrapped
    return await self._propagate_event(
           ^^^^^^^^^^^^^^^^^^^^^^^^^^^^
  File "C:\Users\Treid Computers\PycharmProjects\Final_projects_4\.venv\Lib\site-packages\aiogram\dispatcher\router.py", line 170, in _propagate_event
    response = await router.propagate_event(update_type=update_type, event=event, **kwargs)
               ^^^^^^^^^^^^^^^^^^^^^^^^^^^^^^^^^^^^^^^^^^^^^^^^^^^^^^^^^^^^^^^^^^^^^^^^^^^^
  File "C:\Users\Treid Computers\PycharmProjects\Final_projects_4\.venv\Lib\site-packages\aiogram\dispatcher\router.py", line 142, in propagate_event
    return await observer.wrap_outer_middleware(_wrapped, event=event, data=kwargs)
           ^^^^^^^^^^^^^^^^^^^^^^^^^^^^^^^^^^^^^^^^^^^^^^^^^^^^^^^^^^^^^^^^^^^^^^^^
  File "C:\Users\Treid Computers\PycharmProjects\Final_projects_4\.venv\Lib\site-packages\aiogram\dispatcher\router.py", line 137, in _wrapped
    return await self._propagate_event(
           ^^^^^^^^^^^^^^^^^^^^^^^^^^^^
  File "C:\Users\Treid Computers\PycharmProjects\Final_projects_4\.venv\Lib\site-packages\aiogram\dispatcher\router.py", line 162, in _propagate_event
    response = await observer.trigger(event, **kwargs)
               ^^^^^^^^^^^^^^^^^^^^^^^^^^^^^^^^^^^^^^^
  File "C:\Users\Treid Computers\PycharmProjects\Final_projects_4\.venv\Lib\site-packages\aiogram\dispatcher\event\telegram.py", line 121, in trigger
    return await wrapped_inner(event, kwargs)
           ^^^^^^^^^^^^^^^^^^^^^^^^^^^^^^^^^^
  File "C:\Users\Treid Computers\PycharmProjects\Final_projects_4\.venv\Lib\site-packages\aiogram\dispatcher\event\handler.py", line 43, in call
    return await wrapped()
           ^^^^^^^^^^^^^^^
  File "C:\Users\Treid Computers\PycharmProjects\Final_projects_4\commands_user.py", line 26, in logging_info
    await message.answer_document(file)
  File "C:\Users\Treid Computers\PycharmProjects\Final_projects_4\.venv\Lib\site-packages\aiogram\methods\base.py", line 84, in emit
    return await bot(self)
           ^^^^^^^^^^^^^^^
  File "C:\Users\Treid Computers\PycharmProjects\Final_projects_4\.venv\Lib\site-packages\aiogram\client\bot.py", line 508, in __call__
    return await self.session(self, method, timeout=request_timeout)
           ^^^^^^^^^^^^^^^^^^^^^^^^^^^^^^^^^^^^^^^^^^^^^^^^^^^^^^^^^
  File "C:\Users\Treid Computers\PycharmProjects\Final_projects_4\.venv\Lib\site-packages\aiogram\client\session\base.py", line 254, in __call__
    return cast(TelegramType, await middleware(bot, method))
                              ^^^^^^^^^^^^^^^^^^^^^^^^^^^^^
  File "C:\Users\Treid Computers\PycharmProjects\Final_projects_4\.venv\Lib\site-packages\aiogram\client\session\aiohttp.py", line 178, in make_request
    response = self.check_response(
               ^^^^^^^^^^^^^^^^^^^^
  File "C:\Users\Treid Computers\PycharmProjects\Final_projects_4\.venv\Lib\site-packages\aiogram\client\session\base.py", line 120, in check_response
    raise TelegramBadRequest(method=method, message=description)
aiogram.exceptions.TelegramBadRequest: Telegram server says - Bad Request: file must be non-empty
2024-04-28 13:49:48,730 - ERROR - Cause exception while process update id=564117056 by bot id=6802573095
TelegramNetworkError: HTTP Client says - ClientConnectorError: Cannot connect to host api.telegram.org:443 ssl:default [Превышен таймаут семафора]
Traceback (most recent call last):
  File "C:\Users\Treid Computers\PycharmProjects\Final_projects_4\.venv\Lib\site-packages\aiohttp\connector.py", line 1025, in _wrap_create_connection
    return await self._loop.create_connection(*args, **kwargs)
           ^^^^^^^^^^^^^^^^^^^^^^^^^^^^^^^^^^^^^^^^^^^^^^^^^^^
  File "C:\Users\Treid Computers\AppData\Local\Programs\Python\Python312\Lib\asyncio\base_events.py", line 1099, in create_connection
    raise exceptions[0]
  File "C:\Users\Treid Computers\AppData\Local\Programs\Python\Python312\Lib\asyncio\base_events.py", line 1081, in create_connection
    sock = await self._connect_sock(
           ^^^^^^^^^^^^^^^^^^^^^^^^^
  File "C:\Users\Treid Computers\AppData\Local\Programs\Python\Python312\Lib\asyncio\base_events.py", line 984, in _connect_sock
    await self.sock_connect(sock, address)
  File "C:\Users\Treid Computers\AppData\Local\Programs\Python\Python312\Lib\asyncio\proactor_events.py", line 727, in sock_connect
    return await self._proactor.connect(sock, address)
           ^^^^^^^^^^^^^^^^^^^^^^^^^^^^^^^^^^^^^^^^^^^
  File "C:\Users\Treid Computers\AppData\Local\Programs\Python\Python312\Lib\asyncio\windows_events.py", line 798, in _poll
    value = callback(transferred, key, ov)
            ^^^^^^^^^^^^^^^^^^^^^^^^^^^^^^
  File "C:\Users\Treid Computers\AppData\Local\Programs\Python\Python312\Lib\asyncio\windows_events.py", line 594, in finish_connect
    ov.getresult()
OSError: [WinError 121] Превышен таймаут семафора

The above exception was the direct cause of the following exception:

Traceback (most recent call last):
  File "C:\Users\Treid Computers\PycharmProjects\Final_projects_4\.venv\Lib\site-packages\aiogram\client\session\aiohttp.py", line 170, in make_request
    async with session.post(
  File "C:\Users\Treid Computers\PycharmProjects\Final_projects_4\.venv\Lib\site-packages\aiohttp\client.py", line 1197, in __aenter__
    self._resp = await self._coro
                 ^^^^^^^^^^^^^^^^
  File "C:\Users\Treid Computers\PycharmProjects\Final_projects_4\.venv\Lib\site-packages\aiohttp\client.py", line 581, in _request
    conn = await self._connector.connect(
           ^^^^^^^^^^^^^^^^^^^^^^^^^^^^^^
  File "C:\Users\Treid Computers\PycharmProjects\Final_projects_4\.venv\Lib\site-packages\aiohttp\connector.py", line 544, in connect
    proto = await self._create_connection(req, traces, timeout)
            ^^^^^^^^^^^^^^^^^^^^^^^^^^^^^^^^^^^^^^^^^^^^^^^^^^^
  File "C:\Users\Treid Computers\PycharmProjects\Final_projects_4\.venv\Lib\site-packages\aiohttp\connector.py", line 944, in _create_connection
    _, proto = await self._create_direct_connection(req, traces, timeout)
               ^^^^^^^^^^^^^^^^^^^^^^^^^^^^^^^^^^^^^^^^^^^^^^^^^^^^^^^^^^
  File "C:\Users\Treid Computers\PycharmProjects\Final_projects_4\.venv\Lib\site-packages\aiohttp\connector.py", line 1257, in _create_direct_connection
    raise last_exc
  File "C:\Users\Treid Computers\PycharmProjects\Final_projects_4\.venv\Lib\site-packages\aiohttp\connector.py", line 1226, in _create_direct_connection
    transp, proto = await self._wrap_create_connection(
                    ^^^^^^^^^^^^^^^^^^^^^^^^^^^^^^^^^^^
  File "C:\Users\Treid Computers\PycharmProjects\Final_projects_4\.venv\Lib\site-packages\aiohttp\connector.py", line 1033, in _wrap_create_connection
    raise client_error(req.connection_key, exc) from exc
aiohttp.client_exceptions.ClientConnectorError: Cannot connect to host api.telegram.org:443 ssl:default [Превышен таймаут семафора]

During handling of the above exception, another exception occurred:

Traceback (most recent call last):
  File "C:\Users\Treid Computers\PycharmProjects\Final_projects_4\.venv\Lib\site-packages\aiogram\dispatcher\dispatcher.py", line 309, in _process_update
    response = await self.feed_update(bot, update, **kwargs)
               ^^^^^^^^^^^^^^^^^^^^^^^^^^^^^^^^^^^^^^^^^^^^^
  File "C:\Users\Treid Computers\PycharmProjects\Final_projects_4\.venv\Lib\site-packages\aiogram\dispatcher\dispatcher.py", line 158, in feed_update
    response = await self.update.wrap_outer_middleware(
               ^^^^^^^^^^^^^^^^^^^^^^^^^^^^^^^^^^^^^^^^
  File "C:\Users\Treid Computers\PycharmProjects\Final_projects_4\.venv\Lib\site-packages\aiogram\dispatcher\middlewares\error.py", line 25, in __call__
    return await handler(event, data)
           ^^^^^^^^^^^^^^^^^^^^^^^^^^
  File "C:\Users\Treid Computers\PycharmProjects\Final_projects_4\.venv\Lib\site-packages\aiogram\dispatcher\middlewares\user_context.py", line 49, in __call__
    return await handler(event, data)
           ^^^^^^^^^^^^^^^^^^^^^^^^^^
  File "C:\Users\Treid Computers\PycharmProjects\Final_projects_4\.venv\Lib\site-packages\aiogram\fsm\middleware.py", line 42, in __call__
    return await handler(event, data)
           ^^^^^^^^^^^^^^^^^^^^^^^^^^
  File "C:\Users\Treid Computers\PycharmProjects\Final_projects_4\.venv\Lib\site-packages\aiogram\dispatcher\event\telegram.py", line 121, in trigger
    return await wrapped_inner(event, kwargs)
           ^^^^^^^^^^^^^^^^^^^^^^^^^^^^^^^^^^
  File "C:\Users\Treid Computers\PycharmProjects\Final_projects_4\.venv\Lib\site-packages\aiogram\dispatcher\event\handler.py", line 43, in call
    return await wrapped()
           ^^^^^^^^^^^^^^^
  File "C:\Users\Treid Computers\PycharmProjects\Final_projects_4\.venv\Lib\site-packages\aiogram\dispatcher\dispatcher.py", line 276, in _listen_update
    return await self.propagate_event(update_type=update_type, event=event, **kwargs)
           ^^^^^^^^^^^^^^^^^^^^^^^^^^^^^^^^^^^^^^^^^^^^^^^^^^^^^^^^^^^^^^^^^^^^^^^^^^
  File "C:\Users\Treid Computers\PycharmProjects\Final_projects_4\.venv\Lib\site-packages\aiogram\dispatcher\router.py", line 142, in propagate_event
    return await observer.wrap_outer_middleware(_wrapped, event=event, data=kwargs)
           ^^^^^^^^^^^^^^^^^^^^^^^^^^^^^^^^^^^^^^^^^^^^^^^^^^^^^^^^^^^^^^^^^^^^^^^^
  File "C:\Users\Treid Computers\PycharmProjects\Final_projects_4\.venv\Lib\site-packages\aiogram\dispatcher\router.py", line 137, in _wrapped
    return await self._propagate_event(
           ^^^^^^^^^^^^^^^^^^^^^^^^^^^^
  File "C:\Users\Treid Computers\PycharmProjects\Final_projects_4\.venv\Lib\site-packages\aiogram\dispatcher\router.py", line 170, in _propagate_event
    response = await router.propagate_event(update_type=update_type, event=event, **kwargs)
               ^^^^^^^^^^^^^^^^^^^^^^^^^^^^^^^^^^^^^^^^^^^^^^^^^^^^^^^^^^^^^^^^^^^^^^^^^^^^
  File "C:\Users\Treid Computers\PycharmProjects\Final_projects_4\.venv\Lib\site-packages\aiogram\dispatcher\router.py", line 142, in propagate_event
    return await observer.wrap_outer_middleware(_wrapped, event=event, data=kwargs)
           ^^^^^^^^^^^^^^^^^^^^^^^^^^^^^^^^^^^^^^^^^^^^^^^^^^^^^^^^^^^^^^^^^^^^^^^^
  File "C:\Users\Treid Computers\PycharmProjects\Final_projects_4\.venv\Lib\site-packages\aiogram\dispatcher\router.py", line 137, in _wrapped
    return await self._propagate_event(
           ^^^^^^^^^^^^^^^^^^^^^^^^^^^^
  File "C:\Users\Treid Computers\PycharmProjects\Final_projects_4\.venv\Lib\site-packages\aiogram\dispatcher\router.py", line 162, in _propagate_event
    response = await observer.trigger(event, **kwargs)
               ^^^^^^^^^^^^^^^^^^^^^^^^^^^^^^^^^^^^^^^
  File "C:\Users\Treid Computers\PycharmProjects\Final_projects_4\.venv\Lib\site-packages\aiogram\dispatcher\event\telegram.py", line 121, in trigger
    return await wrapped_inner(event, kwargs)
           ^^^^^^^^^^^^^^^^^^^^^^^^^^^^^^^^^^
  File "C:\Users\Treid Computers\PycharmProjects\Final_projects_4\.venv\Lib\site-packages\aiogram\dispatcher\event\handler.py", line 43, in call
    return await wrapped()
           ^^^^^^^^^^^^^^^
  File "C:\Users\Treid Computers\PycharmProjects\Final_projects_4\commands_user.py", line 26, in logging_info
    await message.answer_document(file)
  File "C:\Users\Treid Computers\PycharmProjects\Final_projects_4\.venv\Lib\site-packages\aiogram\methods\base.py", line 84, in emit
    return await bot(self)
           ^^^^^^^^^^^^^^^
  File "C:\Users\Treid Computers\PycharmProjects\Final_projects_4\.venv\Lib\site-packages\aiogram\client\bot.py", line 508, in __call__
    return await self.session(self, method, timeout=request_timeout)
           ^^^^^^^^^^^^^^^^^^^^^^^^^^^^^^^^^^^^^^^^^^^^^^^^^^^^^^^^^
  File "C:\Users\Treid Computers\PycharmProjects\Final_projects_4\.venv\Lib\site-packages\aiogram\client\session\base.py", line 254, in __call__
    return cast(TelegramType, await middleware(bot, method))
                              ^^^^^^^^^^^^^^^^^^^^^^^^^^^^^
  File "C:\Users\Treid Computers\PycharmProjects\Final_projects_4\.venv\Lib\site-packages\aiogram\client\session\aiohttp.py", line 177, in make_request
    raise TelegramNetworkError(method=method, message=f"{type(e).__name__}: {e}")
aiogram.exceptions.TelegramNetworkError: HTTP Client says - ClientConnectorError: Cannot connect to host api.telegram.org:443 ssl:default [Превышен таймаут семафора]
